#VRML_SIM R2020b utf8
WorldInfo {
  coordinateSystem "NUE"
  contactProperties [
    ContactProperties {
      coulombFriction [
        0.5
      ]
    }
  ]
}
Viewpoint {
  orientation 0.975001921643657 0.20516293688400242 0.08531952953636944 5.070791949282549
  position -1.591135360032796 11.197106096699283 5.412281649012264
}
TexturedBackground {
}
TexturedBackgroundLight {
}
RectangleArena {
  translation -0.472725 0 -0.151121
  floorSize 15 15
  floorTileSize 1 1
}
Robot {
  translation 0.4871948034073767 0.34042345205755314 -0.17011633028470674
  rotation -0.9194031803338507 0.30543117018264676 0.24780958874276823 0.022696640632550454
  children [
    InertialUnit {
      name "imu"
    }
    GPS {
    }
    SickLms291 {
      translation 0 0.335 0
    }
    DEF wheel1 HingeJoint {
      jointParameters DEF wheel1 HingeJointParameters {
        position 0.00013137891603118905
        anchor 0.3 -0.2 0.4
      }
      device [
        DEF wheel1 RotationalMotor {
          name "wheel1"
          acceleration 10
        }
      ]
      endPoint DEF wheel1 Solid {
        translation 0.299999999999999 -0.1999999999999995 0.3999999999999991
        rotation -0.5776316095452806 0.5771716297606023 0.5772474629252332 2.093859416903829
        children [
          Shape {
            appearance Appearance {
              texture ImageTexture {
                url [
                  "/home/dango/dango_file/software/webots/appearance source/fen.jpg"
                ]
              }
            }
            geometry Cylinder {
              height 0.1
              radius 0.15
            }
          }
        ]
        name "solid(1)"
        boundingObject Shape {
          geometry Cylinder {
            height 0.1
            radius 0.15
          }
        }
        physics Physics {
          mass 1
        }
      }
    }
    DEF wheel2 HingeJoint {
      jointParameters DEF wheel1 HingeJointParameters {
        position -7.005732000279786e-05
      }
      device [
        DEF wheel1 RotationalMotor {
          name "wheel2"
          acceleration 10
        }
      ]
      endPoint DEF wheel1 Solid {
        translation -0.2999999999999991 -0.19997197658121843 0.40001401048238233
        rotation -0.5776703771361781 0.5772103664856194 0.577169930090682 2.0939757767457996
        children [
          Shape {
            appearance Appearance {
              texture ImageTexture {
                url [
                  "/home/dango/dango_file/software/webots/appearance source/fen.jpg"
                ]
              }
            }
            geometry Cylinder {
              height 0.1
              radius 0.15
            }
          }
        ]
        boundingObject Shape {
          geometry Cylinder {
            height 0.1
            radius 0.15
          }
        }
        physics Physics {
          mass 1
        }
      }
    }
    DEF wheel3 HingeJoint {
      jointParameters DEF wheel1 HingeJointParameters {
        position 0.03623483067835031
      }
      device [
        DEF wheel1 RotationalMotor {
          name "wheel3"
          acceleration 10
        }
      ]
      endPoint DEF wheel3 Solid {
        translation 0.2999999999999991 -0.18537795725601453 -0.4069828165458416
        rotation -0.5705560744531339 0.5701017280617745 0.5911427793398211 2.0731318832736583
        children [
          Shape {
            appearance Appearance {
              texture ImageTexture {
                url [
                  "/home/dango/dango_file/software/webots/appearance source/fen.jpg"
                ]
              }
            }
            geometry Cylinder {
              height 0.1
              radius 0.15
            }
          }
        ]
        name "solid(2)"
        boundingObject Shape {
          geometry Cylinder {
            height 0.1
            radius 0.15
          }
        }
        physics Physics {
          mass 1
        }
      }
    }
    DEF wheel4 HingeJoint {
      jointParameters DEF wheel1 HingeJointParameters {
        position 0.11509927559062631
      }
      device [
        DEF wheel1 RotationalMotor {
          name "wheel4"
          acceleration 10
        }
      ]
      endPoint DEF wheel1 Solid {
        translation -0.29999999999999893 -0.1527385545019439 -0.42032241668587633
        rotation -0.5541978169287657 0.5537564947264376 0.621464821417656 2.028772067870215
        children [
          Shape {
            appearance Appearance {
              texture ImageTexture {
                url [
                  "/home/dango/dango_file/software/webots/appearance source/fen.jpg"
                ]
              }
            }
            geometry Cylinder {
              height 0.1
              radius 0.15
            }
          }
        ]
        name "solid(3)"
        boundingObject Shape {
          geometry Cylinder {
            height 0.1
            radius 0.15
          }
        }
        physics Physics {
          mass 1
        }
      }
    }
    DEF car_body Shape {
      appearance Appearance {
        texture ImageTexture {
          url [
            "/home/dango/dango_file/software/webots/appearance source/qing lv.jpg"
          ]
        }
      }
      geometry Box {
        size 0.5 0.5 1
      }
    }
  ]
  name "my_car"
  boundingObject Shape {
    geometry Box {
      size 0.1 0.1 0.1
    }
  }
  physics Physics {
    mass 1
  }
  controller "ros"
  controllerArgs [
    "--name=my_car"
  ]
}
WoodenBox {
  translation -3.7282 0.4996075988234097 -2.85312
  rotation -1.919868056395007e-18 1 -3.3253376772682775e-18 2.0944
  size 1 1 1
  mass 1
}
WoodenBox {
  translation 3.43255 0.9993771042524359 -2.27936
  rotation -1.8216755170842427e-19 -1 -1.6116593175360343e-18 -1.0472053071795866
  name "wooden box(2)"
  size 1 2 1
  mass 1
}
WoodenBox {
  translation -2.68234 0.49937710325584006 3.69603
  rotation 3.243337830995349e-18 0.9999999999999999 -3.4613726674949093e-18 2.618
  name "wooden box(1)"
  size 2 1 1
  mass 1
}
Group {
}
